<?xml version="1.0" ?>
<robot name="m710ic70" xmlns:xacro="http://ros.org/wiki/xacro">
 <link name="base_link">
      <visual>
        <origin xyz="0 0 0" rpy="0 0 0"/>
        <geometry>
          <mesh filename="package://fanuc_m710ic_description/meshes/m710ic50/visual/base_link.stl"/>
        </geometry>
          <material name="fanuc_black"/>
      </visual>
      <collision>
        <origin xyz="0 0 0" rpy="0 0 0"/>
        <geometry>
          <mesh filename="package://fanuc_m710ic_description/meshes/m710ic50/collision/base_link.stl"/>
        </geometry>
      </collision>
</link>
<link name="link_1">
      <visual>
        <origin xyz="0 0 0" rpy="0 0 0"/>
        <geometry>
          <mesh filename="package://fanuc_m710ic_description/meshes/m710ic50/visual/link_1.stl"/>
        </geometry>
          <material name="fanuc_yellow"/>
      </visual>
      <collision>
        <origin xyz="0 0 0" rpy="0 0 0"/>
        <geometry>
          <mesh filename="package://fanuc_m710ic_description/meshes/m710ic50/collision/link_1.stl"/>
        </geometry>
      </collision>
    </link>
    <link name="link_2">
      <visual>
        <origin xyz="0 0 0" rpy="0 0 0"/>
        <geometry>
          <mesh filename="package://fanuc_m710ic_description/meshes/m710ic50/visual/link_2.stl"/>
        </geometry>
          <material name="fanuc_yellow"/>
      </visual>
      <collision>
        <origin xyz="0 0 0" rpy="0 0 0"/>
        <geometry>
          <mesh filename="package://fanuc_m710ic_description/meshes/m710ic50/collision/link_2.stl"/>
        </geometry>
      </collision>
    </link>
    <link name="link_3">
      <visual>
        <origin xyz="0 0 0" rpy="0 0 0"/>
        <geometry>
          <mesh filename="package://fanuc_m710ic_description/meshes/m710ic50/visual/link_3.stl"/>
        </geometry>
          <material name="fanuc_yellow"/>
      </visual>
      <collision>
        <origin xyz="0 0 0" rpy="0 0 0"/>
        <geometry>
          <mesh filename="package://fanuc_m710ic_description/meshes/m710ic50/collision/link_3.stl"/>
        </geometry>
      </collision>
    </link>
    <link name="link_4">
      <visual>
        <origin xyz="0 0 0" rpy="0 0 0"/>
        <geometry>
          <mesh filename="package://fanuc_m710ic_description/meshes/m710ic50/visual/link_4.stl"/>
        </geometry>
          <material name="fanuc_yellow"/>
      </visual>
      <collision>
        <origin xyz="0 0 0" rpy="0 0 0"/>
        <geometry>
          <mesh filename="package://fanuc_m710ic_description/meshes/m710ic50/collision/link_4.stl"/>
        </geometry>
      </collision>
    </link>
    <link name="link_5">
      <visual>
        <origin xyz="0 0 0" rpy="0 0 0"/>
        <geometry>
          <mesh filename="package://fanuc_m710ic_description/meshes/m710ic50/visual/link_5.stl"/>
        </geometry>
          <material name="fanuc_yellow"/>
      </visual>
      <collision>
        <origin xyz="0 0 0" rpy="0 0 0"/>
        <geometry>
          <mesh filename="package://fanuc_m710ic_description/meshes/m710ic50/collision/link_5.stl"/>
        </geometry>
      </collision>
    </link>
    <link name="link_6">
      <visual>
        <origin xyz="0 0 0" rpy="0 0 0"/>
        <geometry>
          <mesh filename="package://fanuc_m710ic_description/meshes/m710ic50/visual/link_6.stl"/>
        </geometry>
          <material name="fanuc_black"/>
      </visual>
      <collision>
        <origin xyz="0 0 0" rpy="0 0 0"/>
        <geometry>
          <mesh filename="package://fanuc_m710ic_description/meshes/m710ic50/collision/link_6.stl"/>
        </geometry>
      </collision>
    </link>
    <link name="panda_hand">
        <visual>
            <geometry>
                <mesh filename="package://fanuc_m710ic_description/meshes/m710ic50/visual/hand.dae" />
            </geometry>
        </visual>
        <collision>
            <geometry>
                <mesh filename="package://fanuc_m710ic_description/meshes/m710ic50/collision/hand.stl" />
            </geometry>
        </collision>
    </link>
    <link name="panda_leftfinger">
        <visual>
            <geometry>
                <mesh filename="package://fanuc_m710ic_description/meshes/m710ic50/visual/finger.dae" />
            </geometry>
        </visual>
        <collision>
            <geometry>
                <mesh filename="package://fanuc_m710ic_description/meshes/m710ic50/collision/finger.stl" />
            </geometry>
        </collision>
    </link>
    <link name="panda_rightfinger">
        <visual>
            <origin rpy="0 0 3.14159265359" xyz="0 0 0" />
            <geometry>
                <mesh filename="package://fanuc_m710ic_description/meshes/m710ic50/visual/finger.dae" />
            </geometry>
        </visual>
        <collision>
            <origin rpy="0 0 3.14159265359" xyz="0 0 0" />
            <geometry>
                <mesh filename="package://fanuc_m710ic_description/meshes/m710ic50/collision/finger.stl" />
            </geometry>
        </collision>
    </link>

    <!-- joints: main serial chain -->
    <joint name="joint_1" type="revolute">
      <origin xyz="0 0 0.565" rpy="0 0 0" />
      <parent link="base_link" />
      <child link="link_1" />
      <axis xyz="0 0 1" />
      <limit effort="0" lower="-3.1415" upper="3.1415" velocity="3.0543" />
    </joint>
    <joint name="joint_2" type="revolute">
      <origin xyz="0.150 0 0" rpy="0 0 0"/>
      <parent link="link_1" />
      <child link="link_2" />
      <axis xyz="0 1 0" />
      <limit effort="0" lower="-1.5707" upper="2.3561" velocity="3.0543" />
    </joint>
    <joint name="joint_3" type="revolute">
      <origin xyz="0 0 0.870" rpy="0 0 0"/>
      <parent link="link_2" />
      <child link="link_3" />
      <axis xyz="0 -1 0" />
      <limit effort="0" lower="-2.7925" upper="4.8869" velocity="3.0543" />
    </joint>
    <joint name="joint_4" type="revolute">
      <origin xyz="0 0 0.170" rpy="0 0 0"/>
      <parent link="link_3"/>
      <child link="link_4"/>
      <axis xyz="-1 0 0"/>
      <limit effort="0" lower="-6.2830" upper="6.2830" velocity="4.3633" />
    </joint>
    <joint name="joint_5" type="revolute">
      <origin xyz="1.016 0 0" rpy="0 0 0"/>
      <parent link="link_4"/>
      <child link="link_5"/>
      <axis xyz="0 -1 0"/>
      <limit effort="0" lower="-2.1816" upper="2.1816" velocity="4.3633" />
    </joint>
    <joint name="joint_6" type="revolute">
      <origin xyz="0.175 0 0" rpy="0 0 0"/>
      <parent link="link_5"/>
      <child link="link_6"/>
      <axis xyz="-1 0 0"/>
      <limit effort="0" lower="-6.2831" upper="6.2831" velocity="6.1959" />
    </joint>
    <joint name="panda_hand_joint" type="fixed">
        <parent link="link_6" />
        <child link="panda_hand" />
        <origin rpy="0 1.74 0" xyz="0 0 0" />
    </joint>
    
    <joint name="panda_finger_joint1" type="prismatic">
        <parent link="panda_hand" />
        <child link="panda_leftfinger" />
        <origin rpy="0 0 0" xyz="0 0 0.0584" />
        <axis xyz="0 1 0" />
        <limit effort="20" lower="0.0" upper="0.04" velocity="0.2" />
    </joint>
    <joint name="panda_finger_joint2" type="prismatic">
        <parent link="panda_hand" />
        <child link="panda_rightfinger" />
        <origin rpy="0 0 0" xyz="0 0 0.0584" />
        <axis xyz="0 -1 0" />
        <limit effort="20" lower="0.0" upper="0.04" velocity="0.2" />
        <mimic joint="panda_finger_joint1" />
    </joint>
    <!-- ROS-Industrial 'base' frame: base_link to Fanuc World Coordinates transform -->
    <link name="base" />
    <joint name="base_link-base" type="fixed">
      <origin xyz="0 0 0.565" rpy="0 0 0"/>
      <parent link="base_link"/>
      <child link="base"/>
    </joint>


</robot>